<?xml version="1.0"?>
<robot name="fyp_kal_robot" xmlns:xacro="http://www.ros.org/wiki/xacro" xmlns:gazebo="http://playerstage.sourceforge.net/gazebo/xmlschema/#">

  <xacro:include filename="kal_gazebo.xacro" />

  <!-- Define robot constants -->
  <xacro:property name="base_width" value="0.14"/>
  <xacro:property name="base_length" value="0.19"/>
  <xacro:property name="base_height" value="0.035"/>
  <xacro:property name="top_layer_height" value="0.005"/>
  <xacro:property name="standoff_radius" value="0.0025"/>
  <xacro:property name="standoff_height" value="0.06"/>
  <xacro:property name="wheel_radius" value="0.06"/>
  <xacro:property name="wheel_width" value="0.06"/>
  <xacro:property name="wheel_ygap" value="0.03"/>
  <xacro:property name="wheel_zoff" value="0.0"/>
  <xacro:property name="wheel_xoff" value="0.0"/>

  <!-- Robot Base -->
  <link name="base_link">
    <visual>
      <geometry>
        <box size="${base_length} ${base_width} ${base_height}"/>
      </geometry>
      <material name="White">
        <color rgba="1.0 1.0 1.0 1.0"/>
      </material>
    </visual>
    <collision>
      <geometry>
        <box size="${base_length} ${base_width} ${base_height}"/>
      </geometry>
    </collision>
    <inertial>
      <mass value="1.0"/>
      <origin xyz="0 0 0" rpy="0 0 0"/>
      <inertia ixx="0.01" iyy="0.01" izz="0.01" ixy="0.0" ixz="0.0" iyz="0.0"/>
    </inertial>
  </link>
  
  <!-- Top Layer -->
  <link name="top_layer">
    <visual>
      <geometry>
        <box size="${base_length} ${base_width} ${top_layer_height}"/>
      </geometry>
      <material name="White">
        <color rgba="1.0 1.0 1.0 1.0"/>
      </material>
    </visual>
    <collision>
      <geometry>
        <box size="${base_length} ${base_width} ${top_layer_height}"/>
      </geometry>
    </collision>
    <inertial>
      <mass value="0.1"/> 
      <origin xyz="0 0 0" rpy="0 0 0"/>
      <inertia ixx="0.001" iyy="0.001" izz="0.001" ixy="0.0" ixz="0.0" iyz="0.0"/>
    </inertial>
  </link>
  
  <!-- Standoffs -->
  <xacro:macro name="standoff" params="prefix x y">
    <link name="${prefix}_standoff">
      <visual>
        <origin xyz="0 0 0" rpy="0 0 0"/>
        <geometry>
          <cylinder radius="${standoff_radius}" length="${standoff_height}"/>
        </geometry>
        <material name="Gold">
          <color rgba="1 0.843 0 1.0"/>
        </material>
      </visual>
      <collision>
        <geometry>
          <cylinder radius="${standoff_radius}" length="${standoff_height}"/>
        </geometry>
      </collision>
      <inertial>
        <mass value="0.005"/> 
        <origin xyz="0 0 0" rpy="0 0 0"/>
        <inertia ixx="0.00001" iyy="0.00001" izz="0.00001" ixy="0.0" ixz="0.0" iyz="0.0"/>
      </inertial>
    </link>
    <joint name="${prefix}_standoff_joint" type="fixed">
      <parent link="base_link"/>
      <child link="${prefix}_standoff"/>
      <origin xyz="${x} ${y} ${(base_height/2 + standoff_height/2)}" rpy="0 0 0"/>
    </joint>
  </xacro:macro>
  
  <xacro:standoff prefix="front_left" x="${base_length/2}" y="${base_width/2}"/>
  <xacro:standoff prefix="front_right" x="${base_length/2}" y="${-base_width/2}"/>
  <xacro:standoff prefix="rear_left" x="${-base_length/2}" y="${base_width/2}"/>
  <xacro:standoff prefix="rear_right" x="${-base_length/2}" y="${-base_width/2}"/>
  
  <!-- Top Layer Joint -->
  <joint name="top_layer_joint" type="fixed">
    <parent link="base_link"/>
    <child link="top_layer"/>
    <origin xyz="0 0 ${(base_height + standoff_height - 0.02)}" rpy="0 0 0"/>
  </joint>
  
  <!-- Robot Footprint -->
  <link name="base_footprint"/>

  <joint name="base_joint" type="fixed">
    <parent link="base_link"/>
    <child link="base_footprint"/>
    <origin xyz="0.0 0.0 ${-wheel_radius}" rpy="0 0 0"/>
  </joint>


  <!-- Wheels -->
  <xacro:macro name="wheel" params="prefix x_reflect y_reflect">
    <link name="${prefix}_link">
      <visual>
        <origin xyz="0 0 0" rpy="${pi/2} 0 0"/>
        <geometry>
            <cylinder radius="${wheel_radius}" length="${wheel_width}"/>
        </geometry>
        <material name="Gray">
          <color rgba="0.5 0.5 0.5 1.0"/>
        </material>
      </visual>
      <collision>
        <geometry>
            <cylinder radius="${wheel_radius}" length="${wheel_width}"/>
        </geometry>
      </collision>
      <inertial>
        <mass value="0.1"/>
        <origin xyz="0 0 0" rpy="0 0 0"/>
        <inertia ixx="0.001" iyy="0.001" izz="0.001" ixy="0.0" ixz="0.0" iyz="0.0"/>
      </inertial>
    </link>

    <joint name="${prefix}_joint" type="continuous">
      <parent link="base_link"/>
      <child link="${prefix}_link"/>
      <origin xyz="${x_reflect*(wheel_xoff + (base_length/2))} ${y_reflect*(base_width/2+wheel_ygap)} ${wheel_zoff}" rpy="0 0 0"/>
      <axis xyz="0 1 0"/>
    </joint>
  </xacro:macro>

  <xacro:wheel prefix="drivewhl_l" x_reflect="1" y_reflect="1" />
  <xacro:wheel prefix="drivewhl_r" x_reflect="1" y_reflect="-1" />
  <xacro:wheel prefix="rearwhl_l" x_reflect="-1" y_reflect="1" />
  <xacro:wheel prefix="rearwhl_r" x_reflect="-1" y_reflect="-1" />
</robot>
