<?xml version="1.0"?>

<robot name="new_fyp_kal_robot" xmlns:xacro="http://www.ros.org/wiki/xacro">
	
  <xacro:property name="wheel_radius" value="0.06"/>
  <xacro:property name="wheel_width" value="0.06"/>
  <xacro:property name="wheel_ygap" value="0.03"/>
  <xacro:property name="wheel_zoff" value="0.0"/>
  <xacro:property name="wheel_xoff" value="0.0"/>
  
  
  <!-- Wheels -->
  <xacro:macro name="wheel" params="prefix x_reflect y_reflect">
    <link name="${prefix}_link">
      <visual>
        <origin xyz="0 0 0" rpy="${pi/2} 0 0"/>
        <geometry>
            <cylinder radius="${wheel_radius}" length="${wheel_width}"/>
        </geometry>
        <material name="Gray">
          <color rgba="0.5 0.5 0.5 1.0"/>
        </material>
      </visual>
      <collision>
        <origin xyz="0 0 0" rpy="${pi/2} 0 0"/>
        <geometry>
          <cylinder radius="${wheel_radius}" length="${wheel_width}"/>
        </geometry>
      </collision>
      <xacro:cylinder_inertia m="0.5" r="${wheel_radius}" h="${wheel_width}"/>
    </link>

    <joint name="${prefix}_joint" type="continuous">
      <parent link="base_link"/>
      <child link="${prefix}_link"/>
      <origin xyz="${x_reflect*(wheel_xoff + (base_length/2))} ${y_reflect*(base_width/2+wheel_ygap)} ${wheel_zoff}" rpy="0 0 0"/>
      <axis xyz="0 1 0"/>
    </joint>
  </xacro:macro>

  <xacro:wheel prefix="drivewhl_l" x_reflect="1" y_reflect="1" />
  <xacro:wheel prefix="drivewhl_r" x_reflect="1" y_reflect="-1" />
  <xacro:wheel prefix="rearwhl_l" x_reflect="-1" y_reflect="1" />
  <xacro:wheel prefix="rearwhl_r" x_reflect="-1" y_reflect="-1" />
  
</robot>
